<?xml version="1.0" ?>
<!-- =================================================================================== -->
<!-- |    This document was autogenerated by xacro from raspimouse.urdf.xacro          | -->
<!-- |    EDITING THIS FILE BY HAND IS NOT RECOMMENDED                                 | -->
<!-- =================================================================================== -->
<robot name="raspimouse_with_camera_urg" xmlns:controller="http://playerstage.sourceforge.net/gazebo/xmlschema/#controller" xmlns:interface="http://playerstage.sourceforge.net/gazebo/xmlschema/#interface" xmlns:sensor="http://playerstage.sourceforge.net/gazebo/xmlschema/#sensor">
  <material name="black">
    <color rgba="0.2 0.2 0.2 1.0"/>
  </material>
  <gazebo reference="base_link">
    <mu1>0.1</mu1>
    <mu2>0.1</mu2>
  </gazebo>
  <!-- =============== Link & Joint =============== -->
  <!-- Base -->
  <link name="base_footprint"/>
  <joint name="base_joint" type="fixed">
    <origin xyz="0 0 0.00185"/>
    <parent link="base_footprint"/>
    <child link="base_link"/>
  </joint>
  <link name="base_link">
    <visual>
      <geometry>
        <mesh filename="package://raspimouse_description/meshes/dae/body/raspimouse_body.dae"/>
      </geometry>
    </visual>
    <collision>
      <!-- <geometry> -->
      <!-- <mesh filename="package://raspimouse_description/meshes/dae/body/raspimouse_body.dae" /> -->
      <!-- </geometry> -->
      <origin rpy="0 0 0" xyz="0.005 0 0.040"/>
      <geometry>
        <box size="0.117 0.080 0.080"/>
      </geometry>
    </collision>
    <inertial>
      <origin xyz="-0.005075 0.0 0.03"/>
      <mass value="0.7186"/>
      <inertia ixx="0.0007466666666666666" ixy="0" ixz="0" iyy="0.0009566666666666668" iyz="0" izz="0.0009566666666666668"/>
      <!-- <origin xyz="-0.005075 -0.000427 0.029879" /> -->
      <!-- <inertia ixx="0.001238161833" ixy="0.000000904986" iyy="0.001368529369"
                    ixz="0.000100297310" iyz="0.000022118177" izz="0.000784319117" /> -->
    </inertial>
  </link>
  <joint name="right_wheel_joint" type="continuous">
    <origin rpy="1.57 0 0" xyz="0 -0.0425 0.02215"/>
    <axis xyz="0 0 -1"/>
    <parent link="base_link"/>
    <child link="right_wheel"/>
    <limit effort="70" velocity="90"/>
    <safety_controller k_velocity="10"/>
    <dynamics damping="1.0" friction="1.0"/>
  </joint>
  <link name="right_wheel">
    <visual>
      <geometry>
        <mesh filename="package://raspimouse_description/meshes/dae/wheel/raspimouse_wheel.dae"/>
      </geometry>
    </visual>
    <collision>
      <!-- <geometry> -->
      <!-- <mesh filename="package://raspimouse_description/meshes/dae/wheel/raspimouse_wheel.dae"/> -->
      <!-- </geometry> -->
      <origin xyz="0 0 0.003"/>
      <geometry>
        <cylinder length="0.01" radius="0.024"/>
      </geometry>
      <surface>
        <friction>
          <ode>
            <mu>2</mu>
            <mu2>2</mu2>
            <slip1>0</slip1>
            <slip2>0</slip2>
          </ode>
        </friction>
      </surface>
    </collision>
    <inertial>
      <origin xyz="-0.000107 0 0.002875"/>
      <mass value="0.0113"/>
      <inertia ixx="0.000002208187" ixy="0.000000000001" ixz="0.000000004787" iyy="0.00000218412" iyz="0.000000000003" izz="0.000004078299"/>
    </inertial>
  </link>
  <joint name="left_wheel_joint" type="continuous">
    <origin rpy="-1.57 0 0" xyz="0 0.0425 0.02215"/>
    <axis xyz="0 0 1"/>
    <parent link="base_link"/>
    <child link="left_wheel"/>
    <limit effort="70" velocity="90"/>
    <safety_controller k_velocity="10"/>
    <dynamics damping="1.0" friction="1.0"/>
  </joint>
  <link name="left_wheel">
    <visual>
      <geometry>
        <mesh filename="package://raspimouse_description/meshes/dae/wheel/raspimouse_wheel.dae"/>
      </geometry>
    </visual>
    <collision>
      <!-- <geometry> -->
      <!-- <mesh filename="package://raspimouse_description/meshes/dae/wheel/raspimouse_wheel.dae"/> -->
      <!-- </geometry> -->
      <origin xyz="0 0 0.003"/>
      <geometry>
        <cylinder length="0.01" radius="0.024"/>
      </geometry>
      <surface>
        <friction>
          <ode>
            <mu>2</mu>
            <mu2>2</mu2>
            <slip1>0</slip1>
            <slip2>0</slip2>
          </ode>
        </friction>
      </surface>
    </collision>
    <inertial>
      <origin xyz="-0.000107 0 0.002875"/>
      <mass value="0.0113"/>
      <inertia ixx="0.000002208187" ixy="0.000000000001" ixz="0.000000004787" iyy="0.00000218412" iyz="0.000000000003" izz="0.000004078299"/>
    </inertial>
  </link>
  <!-- Sensors -->
  <link name="lightsensors"/>
  <joint name="lightsensors_joint" type="fixed">
    <parent link="base_link"/>
    <child link="lightsensors"/>
  </joint>
  <joint name="rf_joint" type="fixed">
    <origin rpy="0 0 0" xyz="0.04 -0.045 0.032"/>
    <parent link="lightsensors"/>
    <child link="rf_lightsensor_link"/>
  </joint>
  <link name="rf_lightsensor_link">
    <visual>
      <geometry>
        <box size="0.01 0.005 0.007"/>
      </geometry>
      <material name="Gray">
        <color rgba="0.2 0.2 0.2 1"/>
      </material>
    </visual>
    <inertial>
      <mass value="0.000001"/>
      <origin xyz="0 0 0"/>
      <inertia ixx="0.0001" ixy="0.0" ixz="0.0" iyy="0.0001" iyz="0.0" izz="0.0001"/>
    </inertial>
  </link>
  <joint name="rs_joint" type="fixed">
    <origin rpy="0 0 -1.04" xyz="0.059 -0.01 0.032"/>
    <parent link="lightsensors"/>
    <child link="rs_lightsensor_link"/>
  </joint>
  <link name="rs_lightsensor_link">
    <visual>
      <geometry>
        <box size="0.01 0.005 0.007"/>
      </geometry>
      <material name="Gray">
        <color rgba="0.2 0.2 0.2 1"/>
      </material>
    </visual>
    <inertial>
      <mass value="0.000001"/>
      <origin xyz="0 0 0"/>
      <inertia ixx="0.0001" ixy="0.0" ixz="0.0" iyy="0.0001" iyz="0.0" izz="0.0001"/>
    </inertial>
  </link>
  <joint name="ls_joint" type="fixed">
    <origin rpy="0 0 1.04" xyz="0.059 0.01 0.032"/>
    <parent link="lightsensors"/>
    <child link="ls_lightsensor_link"/>
  </joint>
  <link name="ls_lightsensor_link">
    <visual>
      <geometry>
        <box size="0.01 0.005 0.007"/>
      </geometry>
      <material name="Gray">
        <color rgba="0.2 0.2 0.2 1"/>
      </material>
    </visual>
    <inertial>
      <mass value="0.000001"/>
      <origin xyz="0 0 0"/>
      <inertia ixx="0.0001" ixy="0.0" ixz="0.0" iyy="0.0001" iyz="0.0" izz="0.0001"/>
    </inertial>
  </link>
  <joint name="lf_joint" type="fixed">
    <origin rpy="0 0 0" xyz="0.04 0.045 0.032"/>
    <parent link="lightsensors"/>
    <child link="lf_lightsensor_link"/>
  </joint>
  <link name="lf_lightsensor_link">
    <visual>
      <geometry>
        <box size="0.01 0.005 0.007"/>
      </geometry>
      <material name="Gray">
        <color rgba="0.2 0.2 0.2 1"/>
      </material>
    </visual>
    <inertial>
      <mass value="0.000001"/>
      <origin xyz="0 0 0"/>
      <inertia ixx="0.0001" ixy="0.0" ixz="0.0" iyy="0.0001" iyz="0.0" izz="0.0001"/>
    </inertial>
  </link>
  <joint name="urg_mount_joint" type="fixed">
    <origin rpy="0 0 0" xyz="0 0 0"/>
    <parent link="base_link"/>
    <child link="urg_mount_link"/>
  </joint>
  <link name="urg_mount_link">
    <visual>
      <geometry>
        <mesh filename="package://raspimouse_description/meshes/dae/body/raspimouse_top_plate.dae"/>
      </geometry>
    </visual>
    <collision>
      <origin rpy="0 0 0" xyz="0.005 0 0.0435"/>
      <geometry>
        <box size="0.117 0.080 0.087"/>
      </geometry>
    </collision>
    <inertial>
      <origin xyz="0 0 0.07"/>
      <mass value="0.04"/>
      <inertia ixx="3.334666666666668e-05" ixy="0" ixz="0" iyy="5.6346666666666674e-05" iyz="0" izz="8.966666666666667e-05"/>
    </inertial>
  </link>
  <joint name="laser_joint" type="fixed">
    <origin rpy="0 0 0" xyz="0.0 0.0 0.14060"/>
    <parent link="urg_mount_link"/>
    <child link="laser"/>
  </joint>
  <link name="laser">
    <visual>
      <geometry>
        <mesh filename="package://raspimouse_description/meshes/dae/sensor/urg_optical_axis_center_origin.dae"/>
      </geometry>
    </visual>
    <collision>
      <origin xyz="0 0 -0.01815"/>
      <geometry>
        <cylinder length="0.070" radius="0.025"/>
      </geometry>
    </collision>
    <inertial>
      <mass value="0.16"/>
      <origin xyz="0 0 0"/>
      <inertia ixx="9.033333333333337e-05" ixy="0" ixz="0" iyy="9.033333333333337e-05" iyz="0" izz="5e-05"/>
    </inertial>
  </link>
  <material name="aluminum">
    <color rgba="0.5 0.5 0.5 1"/>
  </material>
  <material name="plastic">
    <color rgba="0.1 0.1 0.1 1"/>
  </material>
  <!-- camera body, with origin at bottom screw mount -->
  <joint name="camera_joint" type="fixed">
    <origin rpy="0 0 0" xyz="0.08 0.0 0.055"/>
    <parent link="base_link"/>
    <child link="camera_bottom_screw_frame"/>
  </joint>
  <link name="camera_bottom_screw_frame"/>
  <joint name="camera_link_joint" type="fixed">
    <origin rpy="0 0 0" xyz="0.010600000000000002 0.0175 0.0125"/>
    <parent link="camera_bottom_screw_frame"/>
    <child link="camera_link"/>
  </joint>
  <link name="camera_link">
    <visual>
      <!-- the mesh origin is at front plate in between the two infrared camera axes -->
      <origin rpy="1.5707963267948966 0 1.5707963267948966" xyz="0.0043 -0.0175 0"/>
      <geometry>
        <mesh filename="package://realsense2_description/meshes/d435.dae"/>
      </geometry>
    </visual>
    <collision>
      <origin rpy="0 0 0" xyz="0 -0.0175 0"/>
      <geometry>
        <box size="0.02505 0.09 0.025"/>
      </geometry>
    </collision>
    <inertial>
      <!-- The following are not reliable values, and should not be used for modeling -->
      <mass value="0.072"/>
      <origin xyz="0 0 0"/>
      <inertia ixx="0.003881243" ixy="0.0" ixz="0.0" iyy="0.000498940" iyz="0.0" izz="0.003879257"/>
    </inertial>
  </link>
  <raspimouse_on_gazebo/>
</robot>
